<sdf version='1.7'>
  <world name='default'>
    <light name='sun' type='directional'>
      <cast_shadows>1</cast_shadows>
      <pose>0 0 10 0 -0 0</pose>
      <diffuse>0.8 0.8 0.8 1</diffuse>
      <specular>0.2 0.2 0.2 1</specular>
      <attenuation>
        <range>1000</range>
        <constant>0.9</constant>
        <linear>0.01</linear>
        <quadratic>0.001</quadratic>
      </attenuation>
      <direction>-0.5 0.1 -0.9</direction>
      <spot>
        <inner_angle>0</inner_angle>
        <outer_angle>0</outer_angle>
        <falloff>0</falloff>
      </spot>
    </light>
    <model name='ground_plane'>
      <static>1</static>
      <link name='link'>
        <collision name='collision'>
          <geometry>
            <plane>
              <normal>0 0 1</normal>
              <size>100 100</size>
            </plane>
          </geometry>
          <surface>
            <contact>
              <collide_bitmask>65535</collide_bitmask>
              <ode/>
            </contact>
            <friction>
              <ode>
                <mu>100</mu>
                <mu2>50</mu2>
              </ode>
              <torsional>
                <ode/>
              </torsional>
            </friction>
            <bounce/>
          </surface>
          <max_contacts>10</max_contacts>
        </collision>
        <visual name='visual'>
          <cast_shadows>0</cast_shadows>
          <geometry>
            <plane>
              <normal>0 0 1</normal>
              <size>100 100</size>
            </plane>
          </geometry>
          <material>
            <script>
              <uri>file://media/materials/scripts/gazebo.material</uri>
              <name>Gazebo/Grey</name>
            </script>
          </material>
        </visual>
        <self_collide>0</self_collide>
        <enable_wind>0</enable_wind>
        <kinematic>0</kinematic>
      </link>
    </model>
    <gravity>0 0 -9.8</gravity>
    <magnetic_field>6e-06 2.3e-05 -4.2e-05</magnetic_field>
    <atmosphere type='adiabatic'/>
    <physics type='ode'>
      <max_step_size>0.001</max_step_size>
      <real_time_factor>1</real_time_factor>
      <real_time_update_rate>1000</real_time_update_rate>
    </physics>
    <scene>
      <ambient>0.4 0.4 0.4 1</ambient>
      <background>0.7 0.7 0.7 1</background>
      <shadows>1</shadows>
    </scene>
    <wind/>
    <spherical_coordinates>
      <surface_model>EARTH_WGS84</surface_model>
      <latitude_deg>0</latitude_deg>
      <longitude_deg>0</longitude_deg>
      <elevation>0</elevation>
      <heading_deg>0</heading_deg>
    </spherical_coordinates>
    <state world_name='default'>
      <sim_time>212 840000000</sim_time>
      <real_time>213 562905699</real_time>
      <wall_time>1661703766 424838245</wall_time>
      <iterations>212840</iterations>
     
      <light name='sun'>
        <pose>0 0 10 0 -0 0</pose>
      </light>
    </state>
    <model name='Panda'>
      <link name='panda_link0'>
        <inertial>
          <pose>-0.025566 -2.9e-05 0.057332 0 -0 0</pose>
          <mass>2.81427</mass>
          <inertia>
            <ixx>0.00753906</ixx>
            <iyy>0.010508</iyy>
            <izz>0.00986493</izz>
            <ixy>-1.50531e-05</ixy>
            <ixz>-0.00121443</ixz>
            <iyz>1.04348e-05</iyz>
          </inertia>
        </inertial>
        <self_collide>0</self_collide>
        <enable_wind>0</enable_wind>
        <kinematic>0</kinematic>
        <pose>0 0 0 0 -0 0</pose>
        <visual name='panda_link0_visual'>
          <geometry>
            <mesh>
              <uri>/home/ubuntu/.ignition/fuel/fuel.ignitionrobotics.org/openrobotics/models/panda with ignition position controller model/2/meshes/visual/link0.dae</uri>
            </mesh>
          </geometry>
          <material>
            <diffuse>1 1 1 1</diffuse>
            <specular>1 1 1 1</specular>
            <pbr>
              <metal>
                <albedo_map>materials/textures/link0_link0_BaseColor.png</albedo_map>
                <normal_map>materials/textures/link0_link0_Normal.png</normal_map>
                <metalness_map>materials/textures/link0_link0_Metallic.png</metalness_map>
                <roughness_map>materials/textures/link0_link0_Roughness.png</roughness_map>
                <environment_map>https://fuel.ignitionrobotics.org/1.0/openrobotics/models/Reflective table/1/files/materials/textures/DepotEnvMap.dds</environment_map>
              </metal>
            </pbr>
            <shader type='pixel'/>
            <script>
              <name>ModelPreview_1::panda_link0::panda_link0_visual_MATERIAL_</name>
              <uri>__default__</uri>
            </script>
          </material>
          <pose>0 0 0 0 -0 0</pose>
          <transparency>0</transparency>
          <cast_shadows>1</cast_shadows>
        </visual>
        <collision name='panda_link0_collision'>
          <laser_retro>0</laser_retro>
          <max_contacts>10</max_contacts>
          <pose>0 0 0 0 -0 0</pose>
          <geometry>
            <mesh>
              <uri>/home/ubuntu/.ignition/fuel/fuel.ignitionrobotics.org/openrobotics/models/panda with ignition position controller model/2/meshes/collision/link0.stl</uri>
              <scale>1 1 1</scale>
            </mesh>
          </geometry>
          <surface>
            <friction>
              <ode>
                <mu>1.05</mu>
                <mu2>1.05</mu2>
                <fdir1>0 0 0</fdir1>
                <slip1>0</slip1>
                <slip2>0</slip2>
              </ode>
              <torsional>
                <coefficient>1</coefficient>
                <patch_radius>0</patch_radius>
                <surface_radius>0</surface_radius>
                <use_patch_radius>1</use_patch_radius>
                <ode>
                  <slip>0</slip>
                </ode>
              </torsional>
            </friction>
            <bounce>
              <restitution_coefficient>0</restitution_coefficient>
              <threshold>1e+06</threshold>
            </bounce>
            <contact>
              <collide_without_contact>0</collide_without_contact>
              <collide_without_contact_bitmask>1</collide_without_contact_bitmask>
              <collide_bitmask>1</collide_bitmask>
              <ode>
                <soft_cfm>0</soft_cfm>
                <soft_erp>0.2</soft_erp>
                <kp>1e+13</kp>
                <kd>1</kd>
                <max_vel>0.01</max_vel>
                <min_depth>0</min_depth>
              </ode>
              <bullet>
                <split_impulse>1</split_impulse>
                <split_impulse_penetration_threshold>-0.01</split_impulse_penetration_threshold>
                <soft_cfm>0</soft_cfm>
                <soft_erp>0.2</soft_erp>
                <kp>1e+13</kp>
                <kd>1</kd>
              </bullet>
            </contact>
          </surface>
        </collision>
      </link>
      <link name='panda_hand'>
        <pose>0.088 1e-06 0.926 -3.14159 -5e-06 0.785398</pose>
        <inertial>
          <pose>-7e-06 0.001524 0.027591 0 -0 0</pose>
          <mass>0.140608</mass>
          <inertia>
            <ixx>0.000536545</ixx>
            <iyy>7.70512e-05</iyy>
            <izz>0.000493818</izz>
            <ixy>1.7912e-08</ixy>
            <ixz>-2.32007e-08</ixz>
            <iyz>4.68115e-08</iyz>
          </inertia>
        </inertial>
        <self_collide>0</self_collide>
        <enable_wind>0</enable_wind>
        <kinematic>0</kinematic>
        <visual name='panda_hand_visual'>
          <pose>0 0 0 0 -0 0</pose>
          <geometry>
            <mesh>
              <uri>/home/ubuntu/.ignition/fuel/fuel.ignitionrobotics.org/openrobotics/models/panda with ignition position controller model/2/meshes/visual/hand.dae</uri>
            </mesh>
          </geometry>
          <material>
            <diffuse>1 1 1 1</diffuse>
            <specular>1 1 1 1</specular>
            <pbr>
              <metal>
                <albedo_map>materials/textures/hand_hand_BaseColor.png</albedo_map>
                <normal_map>materials/textures/hand_hand_Normal.png</normal_map>
                <roughness_map>materials/textures/hand_hand_Roughness.png</roughness_map>
                <environment_map>https://fuel.ignitionrobotics.org/1.0/openrobotics/models/Reflective table/1/files/materials/textures/DepotEnvMap.dds</environment_map>
                <metalness>0.1</metalness>
              </metal>
            </pbr>
            <shader type='pixel'/>
            <script>
              <name>ModelPreview_1::panda_hand::panda_hand_visual_MATERIAL_</name>
              <uri>__default__</uri>
            </script>
          </material>
          <transparency>0</transparency>
          <cast_shadows>1</cast_shadows>
        </visual>
        <collision name='panda_hand_collision'>
          <laser_retro>0</laser_retro>
          <max_contacts>10</max_contacts>
          <pose>0 0 0 0 -0 0</pose>
          <geometry>
            <mesh>
              <uri>/home/ubuntu/.ignition/fuel/fuel.ignitionrobotics.org/openrobotics/models/panda with ignition position controller model/2/meshes/collision/hand.stl</uri>
              <scale>1 1 1</scale>
            </mesh>
          </geometry>
          <surface>
            <friction>
              <ode>
                <mu>1.05</mu>
                <mu2>1.05</mu2>
                <fdir1>0 0 0</fdir1>
                <slip1>0</slip1>
                <slip2>0</slip2>
              </ode>
              <torsional>
                <coefficient>1</coefficient>
                <patch_radius>0</patch_radius>
                <surface_radius>0</surface_radius>
                <use_patch_radius>1</use_patch_radius>
                <ode>
                  <slip>0</slip>
                </ode>
              </torsional>
            </friction>
            <bounce>
              <restitution_coefficient>0</restitution_coefficient>
              <threshold>1e+06</threshold>
            </bounce>
            <contact>
              <collide_without_contact>0</collide_without_contact>
              <collide_without_contact_bitmask>1</collide_without_contact_bitmask>
              <collide_bitmask>1</collide_bitmask>
              <ode>
                <soft_cfm>0</soft_cfm>
                <soft_erp>0.2</soft_erp>
                <kp>1e+13</kp>
                <kd>1</kd>
                <max_vel>0.01</max_vel>
                <min_depth>0</min_depth>
              </ode>
              <bullet>
                <split_impulse>1</split_impulse>
                <split_impulse_penetration_threshold>-0.01</split_impulse_penetration_threshold>
                <soft_cfm>0</soft_cfm>
                <soft_erp>0.2</soft_erp>
                <kp>1e+13</kp>
                <kd>1</kd>
              </bullet>
            </contact>
          </surface>
        </collision>
      </link>
      <link name='panda_leftfinger'>
        <pose>0.088 1e-06 0.8676 -3.14159 -5e-06 0.785398</pose>
        <inertial>
          <pose>-6e-06 0.002278 -0.027712 0 -0 0</pose>
          <mass>0.223845</mass>
          <inertia>
            <ixx>6.74804e-05</ixx>
            <iyy>6.62719e-05</iyy>
            <izz>1.5504e-05</izz>
            <ixy>-4.10274e-09</ixy>
            <ixz>1.86937e-08</ixz>
            <iyz>1.19675e-05</iyz>
          </inertia>
        </inertial>
        <self_collide>0</self_collide>
        <enable_wind>0</enable_wind>
        <kinematic>0</kinematic>
        <visual name='panda_leftfinger_visual'>
          <geometry>
            <mesh>
              <uri>/home/ubuntu/.ignition/fuel/fuel.ignitionrobotics.org/openrobotics/models/panda with ignition position controller model/2/meshes/visual/finger.dae</uri>
            </mesh>
          </geometry>
          <material>
            <diffuse>1 1 1 1</diffuse>
            <specular>1 1 1 1</specular>
            <pbr>
              <metal>
                <albedo_map>materials/textures/finger_finger_BaseColor.png</albedo_map>
                <normal_map>materials/textures/finger_finger_Normal.png</normal_map>
                <roughness_map>materials/textures/finger_finger_Roughness.png</roughness_map>
                <environment_map>https://fuel.ignitionrobotics.org/1.0/openrobotics/models/Reflective table/1/files/materials/textures/DepotEnvMap.dds</environment_map>
                <metallic_map>materials/textures/finger_finger_Metallic.png</metallic_map>
              </metal>
            </pbr>
            <shader type='pixel'/>
            <script>
              <name>ModelPreview_1::panda_leftfinger::panda_leftfinger_visual_MATERIAL_</name>
              <uri>__default__</uri>
            </script>
          </material>
          <pose>0 0 0 0 -0 0</pose>
          <transparency>0</transparency>
          <cast_shadows>1</cast_shadows>
        </visual>
        <collision name='panda_leftfinger_collision'>
          <laser_retro>0</laser_retro>
          <max_contacts>10</max_contacts>
          <pose>0 0 0 0 -0 0</pose>
          <geometry>
            <mesh>
              <uri>/home/ubuntu/.ignition/fuel/fuel.ignitionrobotics.org/openrobotics/models/panda with ignition position controller model/2/meshes/collision/finger.stl</uri>
              <scale>1 1 1</scale>
            </mesh>
          </geometry>
          <surface>
            <friction>
              <ode>
                <mu>2.15</mu>
                <mu2>2.15</mu2>
                <fdir1>0 0 0</fdir1>
                <slip1>0</slip1>
                <slip2>0</slip2>
              </ode>
              <torsional>
                <coefficient>1</coefficient>
                <patch_radius>0</patch_radius>
                <surface_radius>0</surface_radius>
                <use_patch_radius>1</use_patch_radius>
                <ode>
                  <slip>0</slip>
                </ode>
              </torsional>
            </friction>
            <bounce>
              <restitution_coefficient>0</restitution_coefficient>
              <threshold>1e+06</threshold>
            </bounce>
            <contact>
              <collide_without_contact>0</collide_without_contact>
              <collide_without_contact_bitmask>1</collide_without_contact_bitmask>
              <collide_bitmask>1</collide_bitmask>
              <ode>
                <soft_cfm>0</soft_cfm>
                <soft_erp>0.2</soft_erp>
                <kp>1e+13</kp>
                <kd>1</kd>
                <max_vel>0.01</max_vel>
                <min_depth>0</min_depth>
              </ode>
              <bullet>
                <split_impulse>1</split_impulse>
                <split_impulse_penetration_threshold>-0.01</split_impulse_penetration_threshold>
                <soft_cfm>0</soft_cfm>
                <soft_erp>0.2</soft_erp>
                <kp>1e+13</kp>
                <kd>1</kd>
              </bullet>
            </contact>
          </surface>
        </collision>
      </link>
      <link name='panda_link1'>
        <pose>0 0 0.333 0 -0 0</pose>
        <inertial>
          <pose>-0 -0.032496 -0.067582 0 -0 0</pose>
          <mass>2.64332</mass>
          <inertia>
            <ixx>0.0174051</ixx>
            <iyy>0.0153521</iyy>
            <izz>0.00598789</izz>
            <ixy>-8.68799e-09</ixy>
            <ixz>-1.62778e-08</ixz>
            <iyz>0.00451086</iyz>
          </inertia>
        </inertial>
        <self_collide>0</self_collide>
        <enable_wind>0</enable_wind>
        <kinematic>0</kinematic>
        <visual name='panda_link1_visual'>
          <geometry>
            <mesh>
              <uri>/home/ubuntu/.ignition/fuel/fuel.ignitionrobotics.org/openrobotics/models/panda with ignition position controller model/2/meshes/visual/link1.dae</uri>
            </mesh>
          </geometry>
          <material>
            <diffuse>1 1 1 1</diffuse>
            <specular>1 1 1 1</specular>
            <pbr>
              <metal>
                <albedo_map>materials/textures/link1_link1_BaseColor.png</albedo_map>
                <normal_map>materials/textures/link1_link1_Normal.png</normal_map>
                <roughness_map>materials/textures/link1_link1_Roughness.png</roughness_map>
                <environment_map>https://fuel.ignitionrobotics.org/1.0/openrobotics/models/Reflective table/1/files/materials/textures/DepotEnvMap.dds</environment_map>
                <metalness>0.1</metalness>
              </metal>
            </pbr>
            <shader type='pixel'/>
            <script>
              <name>ModelPreview_1::panda_link1::panda_link1_visual_MATERIAL_</name>
              <uri>__default__</uri>
            </script>
          </material>
          <pose>0 0 0 0 -0 0</pose>
          <transparency>0</transparency>
          <cast_shadows>1</cast_shadows>
        </visual>
        <collision name='panda_link1_collision'>
          <laser_retro>0</laser_retro>
          <max_contacts>10</max_contacts>
          <pose>0 0 0 0 -0 0</pose>
          <geometry>
            <mesh>
              <uri>/home/ubuntu/.ignition/fuel/fuel.ignitionrobotics.org/openrobotics/models/panda with ignition position controller model/2/meshes/collision/link1.stl</uri>
              <scale>1 1 1</scale>
            </mesh>
          </geometry>
          <surface>
            <friction>
              <ode>
                <mu>1.05</mu>
                <mu2>1.05</mu2>
                <fdir1>0 0 0</fdir1>
                <slip1>0</slip1>
                <slip2>0</slip2>
              </ode>
              <torsional>
                <coefficient>1</coefficient>
                <patch_radius>0</patch_radius>
                <surface_radius>0</surface_radius>
                <use_patch_radius>1</use_patch_radius>
                <ode>
                  <slip>0</slip>
                </ode>
              </torsional>
            </friction>
            <bounce>
              <restitution_coefficient>0</restitution_coefficient>
              <threshold>1e+06</threshold>
            </bounce>
            <contact>
              <collide_without_contact>0</collide_without_contact>
              <collide_without_contact_bitmask>1</collide_without_contact_bitmask>
              <collide_bitmask>1</collide_bitmask>
              <ode>
                <soft_cfm>0</soft_cfm>
                <soft_erp>0.2</soft_erp>
                <kp>1e+13</kp>
                <kd>1</kd>
                <max_vel>0.01</max_vel>
                <min_depth>0</min_depth>
              </ode>
              <bullet>
                <split_impulse>1</split_impulse>
                <split_impulse_penetration_threshold>-0.01</split_impulse_penetration_threshold>
                <soft_cfm>0</soft_cfm>
                <soft_erp>0.2</soft_erp>
                <kp>1e+13</kp>
                <kd>1</kd>
              </bullet>
            </contact>
          </surface>
        </collision>
      </link>
      <link name='panda_link2'>
        <pose>0 0 0.333 -1.5708 0 0</pose>
        <inertial>
          <pose>0 -0.06861 0.032229 0 -0 0</pose>
          <mass>2.66528</mass>
          <inertia>
            <ixx>0.0177869</ixx>
            <iyy>0.00604413</iyy>
            <izz>0.015711</izz>
            <ixy>8.70636e-08</ixy>
            <ixz>3.75207e-08</ixz>
            <iyz>-0.00459949</iyz>
          </inertia>
        </inertial>
        <self_collide>0</self_collide>
        <enable_wind>0</enable_wind>
        <kinematic>0</kinematic>
        <visual name='panda_link2_visual'>
          <geometry>
            <mesh>
              <uri>/home/ubuntu/.ignition/fuel/fuel.ignitionrobotics.org/openrobotics/models/panda with ignition position controller model/2/meshes/visual/link2.dae</uri>
            </mesh>
          </geometry>
          <material>
            <diffuse>1 1 1 1</diffuse>
            <specular>1 1 1 1</specular>
            <pbr>
              <metal>
                <albedo_map>materials/textures/link2_link2_BaseColor.png</albedo_map>
                <normal_map>materials/textures/link2_link2_Normal.png</normal_map>
                <roughness_map>materials/textures/link2_link2_Roughness.png</roughness_map>
                <environment_map>https://fuel.ignitionrobotics.org/1.0/openrobotics/models/Reflective table/1/files/materials/textures/DepotEnvMap.dds</environment_map>
                <metalness>0.1</metalness>
              </metal>
            </pbr>
            <shader type='pixel'/>
            <script>
              <name>ModelPreview_1::panda_link2::panda_link2_visual_MATERIAL_</name>
              <uri>__default__</uri>
            </script>
          </material>
          <pose>0 0 0 0 -0 0</pose>
          <transparency>0</transparency>
          <cast_shadows>1</cast_shadows>
        </visual>
        <collision name='panda_link2_collision'>
          <laser_retro>0</laser_retro>
          <max_contacts>10</max_contacts>
          <pose>0 0 0 0 -0 0</pose>
          <geometry>
            <mesh>
              <uri>/home/ubuntu/.ignition/fuel/fuel.ignitionrobotics.org/openrobotics/models/panda with ignition position controller model/2/meshes/collision/link2.stl</uri>
              <scale>1 1 1</scale>
            </mesh>
          </geometry>
          <surface>
            <friction>
              <ode>
                <mu>1.05</mu>
                <mu2>1.05</mu2>
                <fdir1>0 0 0</fdir1>
                <slip1>0</slip1>
                <slip2>0</slip2>
              </ode>
              <torsional>
                <coefficient>1</coefficient>
                <patch_radius>0</patch_radius>
                <surface_radius>0</surface_radius>
                <use_patch_radius>1</use_patch_radius>
                <ode>
                  <slip>0</slip>
                </ode>
              </torsional>
            </friction>
            <bounce>
              <restitution_coefficient>0</restitution_coefficient>
              <threshold>1e+06</threshold>
            </bounce>
            <contact>
              <collide_without_contact>0</collide_without_contact>
              <collide_without_contact_bitmask>1</collide_without_contact_bitmask>
              <collide_bitmask>1</collide_bitmask>
              <ode>
                <soft_cfm>0</soft_cfm>
                <soft_erp>0.2</soft_erp>
                <kp>1e+13</kp>
                <kd>1</kd>
                <max_vel>0.01</max_vel>
                <min_depth>0</min_depth>
              </ode>
              <bullet>
                <split_impulse>1</split_impulse>
                <split_impulse_penetration_threshold>-0.01</split_impulse_penetration_threshold>
                <soft_cfm>0</soft_cfm>
                <soft_erp>0.2</soft_erp>
                <kp>1e+13</kp>
                <kd>1</kd>
              </bullet>
            </contact>
          </surface>
        </collision>
      </link>
      <link name='panda_link3'>
        <pose>-0 1e-06 0.649 0 -0 0</pose>
        <inertial>
          <pose>0.046989 0.031637 -0.031704 0 -0 0</pose>
          <mass>2.32937</mass>
          <inertia>
            <ixx>0.00754968</ixx>
            <iyy>0.00968068</iyy>
            <izz>0.00794456</izz>
            <ixy>-0.00243205</ixy>
            <ixz>-0.00325082</ixz>
            <iyz>-0.00213163</iyz>
          </inertia>
        </inertial>
        <self_collide>0</self_collide>
        <enable_wind>0</enable_wind>
        <kinematic>0</kinematic>
        <visual name='panda_link3_visual'>
          <geometry>
            <mesh>
              <uri>/home/ubuntu/.ignition/fuel/fuel.ignitionrobotics.org/openrobotics/models/panda with ignition position controller model/2/meshes/visual/link3.dae</uri>
            </mesh>
          </geometry>
          <material>
            <diffuse>1 1 1 1</diffuse>
            <specular>1 1 1 1</specular>
            <pbr>
              <metal>
                <albedo_map>materials/textures/link3_link3_BaseColor.png</albedo_map>
                <normal_map>materials/textures/link3_link3_Normal.png</normal_map>
                <roughness_map>materials/textures/link3_link3_Roughness.png</roughness_map>
                <environment_map>https://fuel.ignitionrobotics.org/1.0/openrobotics/models/Reflective table/1/files/materials/textures/DepotEnvMap.dds</environment_map>
                <metalness>0.1</metalness>
              </metal>
            </pbr>
            <shader type='pixel'/>
            <script>
              <name>ModelPreview_1::panda_link3::panda_link3_visual_MATERIAL_</name>
              <uri>__default__</uri>
            </script>
          </material>
          <pose>0 0 0 0 -0 0</pose>
          <transparency>0</transparency>
          <cast_shadows>1</cast_shadows>
        </visual>
        <collision name='panda_link3_collision'>
          <laser_retro>0</laser_retro>
          <max_contacts>10</max_contacts>
          <pose>0 0 0 0 -0 0</pose>
          <geometry>
            <mesh>
              <uri>/home/ubuntu/.ignition/fuel/fuel.ignitionrobotics.org/openrobotics/models/panda with ignition position controller model/2/meshes/collision/link3.stl</uri>
              <scale>1 1 1</scale>
            </mesh>
          </geometry>
          <surface>
            <friction>
              <ode>
                <mu>1.05</mu>
                <mu2>1.05</mu2>
                <fdir1>0 0 0</fdir1>
                <slip1>0</slip1>
                <slip2>0</slip2>
              </ode>
              <torsional>
                <coefficient>1</coefficient>
                <patch_radius>0</patch_radius>
                <surface_radius>0</surface_radius>
                <use_patch_radius>1</use_patch_radius>
                <ode>
                  <slip>0</slip>
                </ode>
              </torsional>
            </friction>
            <bounce>
              <restitution_coefficient>0</restitution_coefficient>
              <threshold>1e+06</threshold>
            </bounce>
            <contact>
              <collide_without_contact>0</collide_without_contact>
              <collide_without_contact_bitmask>1</collide_without_contact_bitmask>
              <collide_bitmask>1</collide_bitmask>
              <ode>
                <soft_cfm>0</soft_cfm>
                <soft_erp>0.2</soft_erp>
                <kp>1e+13</kp>
                <kd>1</kd>
                <max_vel>0.01</max_vel>
                <min_depth>0</min_depth>
              </ode>
              <bullet>
                <split_impulse>1</split_impulse>
                <split_impulse_penetration_threshold>-0.01</split_impulse_penetration_threshold>
                <soft_cfm>0</soft_cfm>
                <soft_erp>0.2</soft_erp>
                <kp>1e+13</kp>
                <kd>1</kd>
              </bullet>
            </contact>
          </surface>
        </collision>
      </link>
      <link name='panda_link4'>
        <pose>0.0825 1e-06 0.649 1.5708 -0 0</pose>
        <inertial>
          <pose>-0.036051 0.033707 0.031902 0 -0 0</pose>
          <mass>2.31048</mass>
          <inertia>
            <ixx>0.00776457</ixx>
            <iyy>0.00801578</iyy>
            <izz>0.00995588</izz>
            <ixy>0.00337148</ixy>
            <ixz>-0.00234362</ixz>
            <iyz>0.00229175</iyz>
          </inertia>
        </inertial>
        <self_collide>0</self_collide>
        <enable_wind>0</enable_wind>
        <kinematic>0</kinematic>
        <visual name='panda_link4_visual'>
          <geometry>
            <mesh>
              <uri>/home/ubuntu/.ignition/fuel/fuel.ignitionrobotics.org/openrobotics/models/panda with ignition position controller model/2/meshes/visual/link4.dae</uri>
            </mesh>
          </geometry>
          <material>
            <diffuse>1 1 1 1</diffuse>
            <specular>1 1 1 1</specular>
            <pbr>
              <metal>
                <albedo_map>materials/textures/link4_link4_BaseColor.png</albedo_map>
                <normal_map>materials/textures/link4_link4_Normal.png</normal_map>
                <roughness_map>materials/textures/link4_link4_Roughness.png</roughness_map>
                <environment_map>https://fuel.ignitionrobotics.org/1.0/openrobotics/models/Reflective table/1/files/materials/textures/DepotEnvMap.dds</environment_map>
                <metalness>0.1</metalness>
              </metal>
            </pbr>
            <shader type='pixel'/>
            <script>
              <name>ModelPreview_1::panda_link4::panda_link4_visual_MATERIAL_</name>
              <uri>__default__</uri>
            </script>
          </material>
          <pose>0 0 0 0 -0 0</pose>
          <transparency>0</transparency>
          <cast_shadows>1</cast_shadows>
        </visual>
        <collision name='panda_link4_collision'>
          <laser_retro>0</laser_retro>
          <max_contacts>10</max_contacts>
          <pose>0 0 0 0 -0 0</pose>
          <geometry>
            <mesh>
              <uri>/home/ubuntu/.ignition/fuel/fuel.ignitionrobotics.org/openrobotics/models/panda with ignition position controller model/2/meshes/collision/link4.stl</uri>
              <scale>1 1 1</scale>
            </mesh>
          </geometry>
          <surface>
            <friction>
              <ode>
                <mu>1.05</mu>
                <mu2>1.05</mu2>
                <fdir1>0 0 0</fdir1>
                <slip1>0</slip1>
                <slip2>0</slip2>
              </ode>
              <torsional>
                <coefficient>1</coefficient>
                <patch_radius>0</patch_radius>
                <surface_radius>0</surface_radius>
                <use_patch_radius>1</use_patch_radius>
                <ode>
                  <slip>0</slip>
                </ode>
              </torsional>
            </friction>
            <bounce>
              <restitution_coefficient>0</restitution_coefficient>
              <threshold>1e+06</threshold>
            </bounce>
            <contact>
              <collide_without_contact>0</collide_without_contact>
              <collide_without_contact_bitmask>1</collide_without_contact_bitmask>
              <collide_bitmask>1</collide_bitmask>
              <ode>
                <soft_cfm>0</soft_cfm>
                <soft_erp>0.2</soft_erp>
                <kp>1e+13</kp>
                <kd>1</kd>
                <max_vel>0.01</max_vel>
                <min_depth>0</min_depth>
              </ode>
              <bullet>
                <split_impulse>1</split_impulse>
                <split_impulse_penetration_threshold>-0.01</split_impulse_penetration_threshold>
                <soft_cfm>0</soft_cfm>
                <soft_erp>0.2</soft_erp>
                <kp>1e+13</kp>
                <kd>1</kd>
              </bullet>
            </contact>
          </surface>
        </collision>
      </link>
      <link name='panda_link5'>
        <pose>-0 0 1.033 0 -0 0</pose>
        <inertial>
          <pose>-6e-06 0.061043 -0.104176 0 -0 0</pose>
          <mass>2.62264</mass>
          <inertia>
            <ixx>0.0290705</ixx>
            <iyy>0.0276385</iyy>
            <izz>0.00425111</izz>
            <ixy>6.20874e-07</ixy>
            <ixz>-1.00592e-05</ixz>
            <iyz>-0.00742431</iyz>
          </inertia>
        </inertial>
        <self_collide>0</self_collide>
        <enable_wind>0</enable_wind>
        <kinematic>0</kinematic>
        <visual name='panda_link5_visual'>
          <geometry>
            <mesh>
              <uri>/home/ubuntu/.ignition/fuel/fuel.ignitionrobotics.org/openrobotics/models/panda with ignition position controller model/2/meshes/visual/link5.dae</uri>
            </mesh>
          </geometry>
          <material>
            <diffuse>1 1 1 1</diffuse>
            <specular>1 1 1 1</specular>
            <pbr>
              <metal>
                <albedo_map>materials/textures/link5_link5_BaseColor.png</albedo_map>
                <normal_map>materials/textures/link5_link5_Normal.png</normal_map>
                <roughness_map>materials/textures/link5_link5_Roughness.png</roughness_map>
                <environment_map>https://fuel.ignitionrobotics.org/1.0/openrobotics/models/Reflective table/1/files/materials/textures/DepotEnvMap.dds</environment_map>
                <metalness>0.1</metalness>
              </metal>
            </pbr>
            <shader type='pixel'/>
            <script>
              <name>ModelPreview_1::panda_link5::panda_link5_visual_MATERIAL_</name>
              <uri>__default__</uri>
            </script>
          </material>
          <pose>0 0 0 0 -0 0</pose>
          <transparency>0</transparency>
          <cast_shadows>1</cast_shadows>
        </visual>
        <collision name='panda_link5_collision'>
          <laser_retro>0</laser_retro>
          <max_contacts>10</max_contacts>
          <pose>0 0 0 0 -0 0</pose>
          <geometry>
            <mesh>
              <uri>/home/ubuntu/.ignition/fuel/fuel.ignitionrobotics.org/openrobotics/models/panda with ignition position controller model/2/meshes/collision/link5.stl</uri>
              <scale>1 1 1</scale>
            </mesh>
          </geometry>
          <surface>
            <friction>
              <ode>
                <mu>1.05</mu>
                <mu2>1.05</mu2>
                <fdir1>0 0 0</fdir1>
                <slip1>0</slip1>
                <slip2>0</slip2>
              </ode>
              <torsional>
                <coefficient>1</coefficient>
                <patch_radius>0</patch_radius>
                <surface_radius>0</surface_radius>
                <use_patch_radius>1</use_patch_radius>
                <ode>
                  <slip>0</slip>
                </ode>
              </torsional>
            </friction>
            <bounce>
              <restitution_coefficient>0</restitution_coefficient>
              <threshold>1e+06</threshold>
            </bounce>
            <contact>
              <collide_without_contact>0</collide_without_contact>
              <collide_without_contact_bitmask>1</collide_without_contact_bitmask>
              <collide_bitmask>1</collide_bitmask>
              <ode>
                <soft_cfm>0</soft_cfm>
                <soft_erp>0.2</soft_erp>
                <kp>1e+13</kp>
                <kd>1</kd>
                <max_vel>0.01</max_vel>
                <min_depth>0</min_depth>
              </ode>
              <bullet>
                <split_impulse>1</split_impulse>
                <split_impulse_penetration_threshold>-0.01</split_impulse_penetration_threshold>
                <soft_cfm>0</soft_cfm>
                <soft_erp>0.2</soft_erp>
                <kp>1e+13</kp>
                <kd>1</kd>
              </bullet>
            </contact>
          </surface>
        </collision>
      </link>
      <link name='panda_link6'>
        <pose>-0 0 1.033 1.5708 -0 0</pose>
        <inertial>
          <pose>0.051051 0.009108 0.010634 0 -0 0</pose>
          <mass>1.50258</mass>
          <inertia>
            <ixx>0.00294056</ixx>
            <iyy>0.00392105</iyy>
            <izz>0.00541156</izz>
            <ixy>-0.000423911</ixy>
            <ixz>0.000610008</ixz>
            <iyz>0.000126475</iyz>
          </inertia>
        </inertial>
        <self_collide>0</self_collide>
        <enable_wind>0</enable_wind>
        <kinematic>0</kinematic>
        <visual name='panda_link6_visual'>
          <geometry>
            <mesh>
              <uri>/home/ubuntu/.ignition/fuel/fuel.ignitionrobotics.org/openrobotics/models/panda with ignition position controller model/2/meshes/visual/link6.dae</uri>
            </mesh>
          </geometry>
          <material>
            <diffuse>1 1 1 1</diffuse>
            <specular>1 1 1 1</specular>
            <pbr>
              <metal>
                <albedo_map>materials/textures/link6_link6_BaseColor.png</albedo_map>
                <normal_map>materials/textures/link6_link6_Normal.png</normal_map>
                <roughness_map>materials/textures/link6_link6_Roughness.png</roughness_map>
                <environment_map>https://fuel.ignitionrobotics.org/1.0/openrobotics/models/Reflective table/1/files/materials/textures/DepotEnvMap.dds</environment_map>
                <metalness>0.1</metalness>
              </metal>
            </pbr>
            <shader type='pixel'/>
            <script>
              <name>ModelPreview_1::panda_link6::panda_link6_visual_MATERIAL_</name>
              <uri>__default__</uri>
            </script>
          </material>
          <pose>0 0 0 0 -0 0</pose>
          <transparency>0</transparency>
          <cast_shadows>1</cast_shadows>
        </visual>
        <collision name='panda_link6_collision'>
          <laser_retro>0</laser_retro>
          <max_contacts>10</max_contacts>
          <pose>0 0 0 0 -0 0</pose>
          <geometry>
            <mesh>
              <uri>/home/ubuntu/.ignition/fuel/fuel.ignitionrobotics.org/openrobotics/models/panda with ignition position controller model/2/meshes/collision/link6.stl</uri>
              <scale>1 1 1</scale>
            </mesh>
          </geometry>
          <surface>
            <friction>
              <ode>
                <mu>1.05</mu>
                <mu2>1.05</mu2>
                <fdir1>0 0 0</fdir1>
                <slip1>0</slip1>
                <slip2>0</slip2>
              </ode>
              <torsional>
                <coefficient>1</coefficient>
                <patch_radius>0</patch_radius>
                <surface_radius>0</surface_radius>
                <use_patch_radius>1</use_patch_radius>
                <ode>
                  <slip>0</slip>
                </ode>
              </torsional>
            </friction>
            <bounce>
              <restitution_coefficient>0</restitution_coefficient>
              <threshold>1e+06</threshold>
            </bounce>
            <contact>
              <collide_without_contact>0</collide_without_contact>
              <collide_without_contact_bitmask>1</collide_without_contact_bitmask>
              <collide_bitmask>1</collide_bitmask>
              <ode>
                <soft_cfm>0</soft_cfm>
                <soft_erp>0.2</soft_erp>
                <kp>1e+13</kp>
                <kd>1</kd>
                <max_vel>0.01</max_vel>
                <min_depth>0</min_depth>
              </ode>
              <bullet>
                <split_impulse>1</split_impulse>
                <split_impulse_penetration_threshold>-0.01</split_impulse_penetration_threshold>
                <soft_cfm>0</soft_cfm>
                <soft_erp>0.2</soft_erp>
                <kp>1e+13</kp>
                <kd>1</kd>
              </bullet>
            </contact>
          </surface>
        </collision>
      </link>
      <link name='panda_link7'>
        <pose>0.088 0 1.033 -3.14159 0 0</pose>
        <inertial>
          <pose>0.01097 0.010797 0.065041 0 -0 0</pose>
          <mass>0.523767</mass>
          <inertia>
            <ixx>0.000862147</ixx>
            <iyy>0.00086131</iyy>
            <izz>0.000696114</izz>
            <ixy>-0.000118711</ixy>
            <ixz>3.8666e-05</ixz>
            <iyz>-9.05784e-05</iyz>
          </inertia>
        </inertial>
        <self_collide>0</self_collide>
        <enable_wind>0</enable_wind>
        <kinematic>0</kinematic>
        <visual name='panda_link7_visual'>
          <geometry>
            <mesh>
              <uri>/home/ubuntu/.ignition/fuel/fuel.ignitionrobotics.org/openrobotics/models/panda with ignition position controller model/2/meshes/visual/link7.dae</uri>
            </mesh>
          </geometry>
          <material>
            <diffuse>1 1 1 1</diffuse>
            <specular>1 1 1 1</specular>
            <pbr>
              <metal>
                <albedo_map>materials/textures/link7_link7_BaseColor.png</albedo_map>
                <normal_map>materials/textures/link7_link7_Normal.png</normal_map>
                <metalness_map>materials/textures/link7_link7_Metallic.png</metalness_map>
                <roughness_map>materials/textures/link7_link7_Roughness.png</roughness_map>
                <environment_map>https://fuel.ignitionrobotics.org/1.0/openrobotics/models/Reflective table/1/files/materials/textures/DepotEnvMap.dds</environment_map>
              </metal>
            </pbr>
            <shader type='pixel'/>
            <script>
              <name>ModelPreview_1::panda_link7::panda_link7_visual_MATERIAL_</name>
              <uri>__default__</uri>
            </script>
          </material>
          <pose>0 0 0 0 -0 0</pose>
          <transparency>0</transparency>
          <cast_shadows>1</cast_shadows>
        </visual>
        <collision name='panda_link7_collision'>
          <laser_retro>0</laser_retro>
          <max_contacts>10</max_contacts>
          <pose>0 0 0 0 -0 0</pose>
          <geometry>
            <mesh>
              <uri>/home/ubuntu/.ignition/fuel/fuel.ignitionrobotics.org/openrobotics/models/panda with ignition position controller model/2/meshes/collision/link7.stl</uri>
              <scale>1 1 1</scale>
            </mesh>
          </geometry>
          <surface>
            <friction>
              <ode>
                <mu>1.05</mu>
                <mu2>1.05</mu2>
                <fdir1>0 0 0</fdir1>
                <slip1>0</slip1>
                <slip2>0</slip2>
              </ode>
              <torsional>
                <coefficient>1</coefficient>
                <patch_radius>0</patch_radius>
                <surface_radius>0</surface_radius>
                <use_patch_radius>1</use_patch_radius>
                <ode>
                  <slip>0</slip>
                </ode>
              </torsional>
            </friction>
            <bounce>
              <restitution_coefficient>0</restitution_coefficient>
              <threshold>1e+06</threshold>
            </bounce>
            <contact>
              <collide_without_contact>0</collide_without_contact>
              <collide_without_contact_bitmask>1</collide_without_contact_bitmask>
              <collide_bitmask>1</collide_bitmask>
              <ode>
                <soft_cfm>0</soft_cfm>
                <soft_erp>0.2</soft_erp>
                <kp>1e+13</kp>
                <kd>1</kd>
                <max_vel>0.01</max_vel>
                <min_depth>0</min_depth>
              </ode>
              <bullet>
                <split_impulse>1</split_impulse>
                <split_impulse_penetration_threshold>-0.01</split_impulse_penetration_threshold>
                <soft_cfm>0</soft_cfm>
                <soft_erp>0.2</soft_erp>
                <kp>1e+13</kp>
                <kd>1</kd>
              </bullet>
            </contact>
          </surface>
        </collision>
      </link>
      <link name='panda_link8'>
        <pose>0.088 1e-06 0.823 -3.14159 -5e-06 0.785398</pose>
        <self_collide>0</self_collide>
        <inertial>
          <pose>0 0 0 0 -0 0</pose>
          <inertia>
            <ixx>1</ixx>
            <ixy>0</ixy>
            <ixz>0</ixz>
            <iyy>1</iyy>
            <iyz>0</iyz>
            <izz>1</izz>
          </inertia>
          <mass>1</mass>
        </inertial>
        <enable_wind>0</enable_wind>
        <kinematic>0</kinematic>
      </link>
      <link name='panda_rightfinger'>
        <pose>0.088 1e-06 0.8676 -3.14159 -5e-06 0.785398</pose>
        <inertial>
          <pose>-6e-06 0.002278 -0.027712 0 -0 3.14159</pose>
          <mass>0.223845</mass>
          <inertia>
            <ixx>6.74804e-05</ixx>
            <iyy>6.62719e-05</iyy>
            <izz>1.5504e-05</izz>
            <ixy>-4.10274e-09</ixy>
            <ixz>1.86937e-08</ixz>
            <iyz>1.19675e-05</iyz>
          </inertia>
        </inertial>
        <self_collide>0</self_collide>
        <enable_wind>0</enable_wind>
        <kinematic>0</kinematic>
        <visual name='panda_rightfinger_visual'>
          <pose>0 0 0 0 -0 3.14159</pose>
          <geometry>
            <mesh>
              <uri>/home/ubuntu/.ignition/fuel/fuel.ignitionrobotics.org/openrobotics/models/panda with ignition position controller model/2/meshes/visual/finger.dae</uri>
            </mesh>
          </geometry>
          <material>
            <diffuse>1 1 1 1</diffuse>
            <specular>1 1 1 1</specular>
            <pbr>
              <metal>
                <albedo_map>materials/textures/finger_finger_BaseColor.png</albedo_map>
                <normal_map>materials/textures/finger_finger_Normal.png</normal_map>
                <roughness_map>materials/textures/finger_finger_Roughness.png</roughness_map>
                <environment_map>https://fuel.ignitionrobotics.org/1.0/openrobotics/models/Reflective table/1/files/materials/textures/DepotEnvMap.dds</environment_map>
                <metalness>0.1</metalness>
              </metal>
            </pbr>
            <shader type='pixel'/>
            <script>
              <name>ModelPreview_1::panda_rightfinger::panda_rightfinger_visual_MATERIAL_</name>
              <uri>__default__</uri>
            </script>
          </material>
          <transparency>0</transparency>
          <cast_shadows>1</cast_shadows>
        </visual>
        <collision name='panda_rightfinger_collision'>
          <laser_retro>0</laser_retro>
          <max_contacts>10</max_contacts>
          <pose>0 0 0 0 -0 3.14159</pose>
          <geometry>
            <mesh>
              <uri>/home/ubuntu/.ignition/fuel/fuel.ignitionrobotics.org/openrobotics/models/panda with ignition position controller model/2/meshes/collision/finger.stl</uri>
              <scale>1 1 1</scale>
            </mesh>
          </geometry>
          <surface>
            <friction>
              <ode>
                <mu>2.15</mu>
                <mu2>2.15</mu2>
                <fdir1>0 0 0</fdir1>
                <slip1>0</slip1>
                <slip2>0</slip2>
              </ode>
              <torsional>
                <coefficient>1</coefficient>
                <patch_radius>0</patch_radius>
                <surface_radius>0</surface_radius>
                <use_patch_radius>1</use_patch_radius>
                <ode>
                  <slip>0</slip>
                </ode>
              </torsional>
            </friction>
            <bounce>
              <restitution_coefficient>0</restitution_coefficient>
              <threshold>1e+06</threshold>
            </bounce>
            <contact>
              <collide_without_contact>0</collide_without_contact>
              <collide_without_contact_bitmask>1</collide_without_contact_bitmask>
              <collide_bitmask>1</collide_bitmask>
              <ode>
                <soft_cfm>0</soft_cfm>
                <soft_erp>0.2</soft_erp>
                <kp>1e+13</kp>
                <kd>1</kd>
                <max_vel>0.01</max_vel>
                <min_depth>0</min_depth>
              </ode>
              <bullet>
                <split_impulse>1</split_impulse>
                <split_impulse_penetration_threshold>-0.01</split_impulse_penetration_threshold>
                <soft_cfm>0</soft_cfm>
                <soft_erp>0.2</soft_erp>
                <kp>1e+13</kp>
                <kd>1</kd>
              </bullet>
            </contact>
          </surface>
        </collision>
      </link>
      <joint name='end_effector_frame_fixed_joint' type='fixed'>
        <parent>panda_hand</parent>
        <child>panda_link8</child>
        <pose>-0 0 -0 0 -0 0</pose>
        <physics>
          <ode>
            <limit>
              <cfm>0</cfm>
              <erp>0.2</erp>
            </limit>
            <suspension>
              <cfm>0</cfm>
              <erp>0.2</erp>
            </suspension>
          </ode>
        </physics>
      </joint>
      <joint name='panda_finger_joint1' type='prismatic'>
        <parent>panda_hand</parent>
        <child>panda_leftfinger</child>
        <pose>-0 0 -0 0 -0 0</pose>
        <axis>
          <xyz>0 1 0</xyz>
          <limit>
            <lower>0</lower>
            <upper>0.04</upper>
            <effort>20</effort>
            <velocity>0.2</velocity>
          </limit>
          <dynamics>
            <spring_reference>0</spring_reference>
            <spring_stiffness>0</spring_stiffness>
            <damping>10</damping>
            <friction>0.5</friction>
          </dynamics>
        </axis>
        <physics>
          <ode>
            <limit>
              <cfm>0</cfm>
              <erp>0.2</erp>
            </limit>
            <suspension>
              <cfm>0</cfm>
              <erp>0.2</erp>
            </suspension>
          </ode>
        </physics>
      </joint>
      <joint name='panda_finger_joint2' type='prismatic'>
        <parent>panda_hand</parent>
        <child>panda_rightfinger</child>
        <pose>-0 0 -0 0 -0 0</pose>
        <axis>
          <xyz>0 -1 0</xyz>
          <limit>
            <lower>0</lower>
            <upper>0.04</upper>
            <effort>20</effort>
            <velocity>0.2</velocity>
          </limit>
          <dynamics>
            <spring_reference>0</spring_reference>
            <spring_stiffness>0</spring_stiffness>
            <damping>10</damping>
            <friction>0.5</friction>
          </dynamics>
        </axis>
        <physics>
          <ode>
            <limit>
              <cfm>0</cfm>
              <erp>0.2</erp>
            </limit>
            <suspension>
              <cfm>0</cfm>
              <erp>0.2</erp>
            </suspension>
          </ode>
        </physics>
      </joint>
      <joint name='panda_hand_joint' type='fixed'>
        <parent>panda_link7</parent>
        <child>panda_hand</child>
        <pose>-0 0 -0 -0 -0 -0</pose>
        <physics>
          <ode>
            <limit>
              <cfm>0</cfm>
              <erp>0.2</erp>
            </limit>
            <suspension>
              <cfm>0</cfm>
              <erp>0.2</erp>
            </suspension>
          </ode>
        </physics>
      </joint>
      <joint name='panda_joint1' type='revolute'>
        <parent>panda_link0</parent>
        <child>panda_link1</child>
        <pose>0 0 0 0 -0 0</pose>
        <axis>
          <xyz>0 0 1</xyz>
          <limit>
            <lower>-2.89725</lower>
            <upper>2.89725</upper>
            <effort>87</effort>
            <velocity>2.61799</velocity>
          </limit>
          <dynamics>
            <spring_reference>0</spring_reference>
            <spring_stiffness>0</spring_stiffness>
            <damping>21.75</damping>
            <friction>3.48</friction>
          </dynamics>
        </axis>
        <physics>
          <ode>
            <limit>
              <cfm>0</cfm>
              <erp>0.2</erp>
            </limit>
            <suspension>
              <cfm>0</cfm>
              <erp>0.2</erp>
            </suspension>
          </ode>
        </physics>
      </joint>
      <joint name='panda_joint2' type='revolute'>
        <parent>panda_link1</parent>
        <child>panda_link2</child>
        <pose>0 -0 -0 0 -0 0</pose>
        <axis>
          <xyz>0 0 1</xyz>
          <limit>
            <lower>-1.76278</lower>
            <upper>1.76278</upper>
            <effort>87</effort>
            <velocity>2.61799</velocity>
          </limit>
          <dynamics>
            <spring_reference>0</spring_reference>
            <spring_stiffness>0</spring_stiffness>
            <damping>21.75</damping>
            <friction>3.48</friction>
          </dynamics>
        </axis>
        <physics>
          <ode>
            <limit>
              <cfm>0</cfm>
              <erp>0.2</erp>
            </limit>
            <suspension>
              <cfm>0</cfm>
              <erp>0.2</erp>
            </suspension>
          </ode>
        </physics>
      </joint>
      <joint name='panda_joint3' type='revolute'>
        <parent>panda_link2</parent>
        <child>panda_link3</child>
        <pose>0 0 0 0 -0 0</pose>
        <axis>
          <xyz>0 0 1</xyz>
          <limit>
            <lower>-2.89725</lower>
            <upper>2.89725</upper>
            <effort>87</effort>
            <velocity>2.61799</velocity>
          </limit>
          <dynamics>
            <spring_reference>0</spring_reference>
            <spring_stiffness>0</spring_stiffness>
            <damping>21.75</damping>
            <friction>3.48</friction>
          </dynamics>
        </axis>
        <physics>
          <ode>
            <limit>
              <cfm>0</cfm>
              <erp>0.2</erp>
            </limit>
            <suspension>
              <cfm>0</cfm>
              <erp>0.2</erp>
            </suspension>
          </ode>
        </physics>
      </joint>
      <joint name='panda_joint4' type='revolute'>
        <parent>panda_link3</parent>
        <child>panda_link4</child>
        <pose>-0 0 -0 0 -0 0</pose>
        <axis>
          <xyz>0 0 1</xyz>
          <limit>
            <lower>-3.07178</lower>
            <upper>-0.0698132</upper>
            <effort>87</effort>
            <velocity>2.61799</velocity>
          </limit>
          <dynamics>
            <spring_reference>0</spring_reference>
            <spring_stiffness>0</spring_stiffness>
            <damping>21.75</damping>
            <friction>3.48</friction>
          </dynamics>
        </axis>
        <physics>
          <ode>
            <limit>
              <cfm>0</cfm>
              <erp>0.2</erp>
            </limit>
            <suspension>
              <cfm>0</cfm>
              <erp>0.2</erp>
            </suspension>
          </ode>
        </physics>
      </joint>
      <joint name='panda_joint5' type='revolute'>
        <parent>panda_link4</parent>
        <child>panda_link5</child>
        <pose>0 0 -0 0 -0 0</pose>
        <axis>
          <xyz>0 0 1</xyz>
          <limit>
            <lower>-2.89725</lower>
            <upper>2.89725</upper>
            <effort>12</effort>
            <velocity>3.14159</velocity>
          </limit>
          <dynamics>
            <spring_reference>0</spring_reference>
            <spring_stiffness>0</spring_stiffness>
            <damping>3</damping>
            <friction>0.48</friction>
          </dynamics>
        </axis>
        <physics>
          <ode>
            <limit>
              <cfm>0</cfm>
              <erp>0.2</erp>
            </limit>
            <suspension>
              <cfm>0</cfm>
              <erp>0.2</erp>
            </suspension>
          </ode>
        </physics>
      </joint>
      <joint name='panda_joint6' type='revolute'>
        <parent>panda_link5</parent>
        <child>panda_link6</child>
        <pose>0 0 -0 0 -0 0</pose>
        <axis>
          <xyz>0 0 1</xyz>
          <limit>
            <lower>-0.0174533</lower>
            <upper>3.75246</upper>
            <effort>12</effort>
            <velocity>3.14159</velocity>
          </limit>
          <dynamics>
            <spring_reference>0</spring_reference>
            <spring_stiffness>0</spring_stiffness>
            <damping>3</damping>
            <friction>0.48</friction>
          </dynamics>
        </axis>
        <physics>
          <ode>
            <limit>
              <cfm>0</cfm>
              <erp>0.2</erp>
            </limit>
            <suspension>
              <cfm>0</cfm>
              <erp>0.2</erp>
            </suspension>
          </ode>
        </physics>
      </joint>
      <joint name='panda_joint7' type='revolute'>
        <parent>panda_link6</parent>
        <child>panda_link7</child>
        <pose>-0 -0 -0 0 -0 0</pose>
        <axis>
          <xyz>0 0 1</xyz>
          <limit>
            <lower>-2.89725</lower>
            <upper>2.89725</upper>
            <effort>12</effort>
            <velocity>3.14159</velocity>
          </limit>
          <dynamics>
            <spring_reference>0</spring_reference>
            <spring_stiffness>0</spring_stiffness>
            <damping>3</damping>
            <friction>0.48</friction>
          </dynamics>
        </axis>
        <physics>
          <ode>
            <limit>
              <cfm>0</cfm>
              <erp>0.2</erp>
            </limit>
            <suspension>
              <cfm>0</cfm>
              <erp>0.2</erp>
            </suspension>
          </ode>
        </physics>
      </joint>
      <static>1</static>
      <allow_auto_disable>1</allow_auto_disable>
      <plugin name='ignition::gazebo::systems::JointPositionController' filename='ignition-gazebo-joint-position-controller-system'>
        <joint_name>panda_finger_joint2</joint_name>
        <p_gain>100</p_gain>
        <d_gain>50</d_gain>
        <i_gain>0</i_gain>
        <i_min>-1</i_min>
        <i_max>1</i_max>
        <cmd_min>-20</cmd_min>
        <cmd_max>20</cmd_max>
      </plugin>
      <pose>0.00329 0.007508 0 -1e-06 5e-06 2e-06</pose>
    </model>
    <model name='aws_robomaker_warehouse_Bucket_01'>
      <link name='body'>
        <pose>0 0 0 0 -0 0</pose>
        <self_collide>0</self_collide>
        <kinematic>0</kinematic>
        <gravity>1</gravity>
        <visual name='visual'>
          <geometry>
            <mesh>
              <uri>/home/ubuntu/.ignition/fuel/fuel.ignitionrobotics.org/openrobotics/models/aws_robomaker_warehouse_bucket_01/1/meshes/aws_robomaker_warehouse_Bucket_01_visual.DAE</uri>
            </mesh>
          </geometry>
          <meta>
            <layer>1</layer>
          </meta>
        </visual>
        <collision name='collision_0'>
          <laser_retro>0</laser_retro>
          <max_contacts>10</max_contacts>
          <pose>0 0 0 0 -0 0</pose>
          <geometry>
            <mesh>
              <uri>/home/ubuntu/.ignition/fuel/fuel.ignitionrobotics.org/openrobotics/models/aws_robomaker_warehouse_bucket_01/1/meshes/aws_robomaker_warehouse_Bucket_01_collision.DAE</uri>
              <scale>1 1 1</scale>
            </mesh>
          </geometry>
          <surface>
            <friction>
              <ode>
                <mu>0.4</mu>
                <mu2>0.4</mu2>
                <fdir1>0 0 0</fdir1>
                <slip1>0</slip1>
                <slip2>0</slip2>
              </ode>
              <torsional>
                <coefficient>1</coefficient>
                <patch_radius>0</patch_radius>
                <surface_radius>0</surface_radius>
                <use_patch_radius>1</use_patch_radius>
                <ode>
                  <slip>0</slip>
                </ode>
              </torsional>
            </friction>
            <contact>
              <ode/>
            </contact>
            <bounce/>
          </surface>
        </collision>
        <enable_wind>0</enable_wind>
      </link>
      <static>1</static>
      <pose>0.780378 -1.31112 0 0 -0 0</pose>
    </model>
    <model name='aws_robomaker_warehouse_TrashCanC_01'>
      <link name='link'>
        <collision name='collision'>
          <geometry>
            <mesh>
              <uri>/home/ubuntu/.ignition/fuel/fuel.ignitionrobotics.org/openrobotics/models/aws_robomaker_warehouse_trashcanc_01/2/meshes/aws_robomaker_warehouse_TrashCanC_01_collision.DAE</uri>
            </mesh>
          </geometry>
          <surface>
            <friction>
              <ode>
                <mu>0.4</mu>
                <mu2>0.4</mu2>
                <fdir1>0 0 0</fdir1>
                <slip1>0</slip1>
                <slip2>0</slip2>
              </ode>
              <torsional>
                <ode/>
              </torsional>
            </friction>
            <contact>
              <ode/>
            </contact>
            <bounce/>
          </surface>
          <max_contacts>10</max_contacts>
        </collision>
        <visual name='visual'>
          <geometry>
            <mesh>
              <uri>/home/ubuntu/.ignition/fuel/fuel.ignitionrobotics.org/openrobotics/models/aws_robomaker_warehouse_trashcanc_01/2/meshes/aws_robomaker_warehouse_TrashCanC_01_visual.DAE</uri>
            </mesh>
          </geometry>
          <meta>
            <layer>1</layer>
          </meta>
        </visual>
        <self_collide>0</self_collide>
        <enable_wind>0</enable_wind>
        <kinematic>0</kinematic>
      </link>
      <static>1</static>
      <pose>-0.142748 2.09632 0 0 -0 0</pose>
    </model>
    <model name='aws_robomaker_warehouse_ShelfE_01'>
      <link name='link'>
        <collision name='collision'>
          <geometry>
            <mesh>
              <uri>/home/ubuntu/.ignition/fuel/fuel.ignitionrobotics.org/openrobotics/models/aws_robomaker_warehouse_shelfe_01/2/meshes/aws_robomaker_warehouse_ShelfE_01_collision.DAE</uri>
            </mesh>
          </geometry>
          <surface>
            <friction>
              <ode>
                <mu>0.2</mu>
                <mu2>0.2</mu2>
                <fdir1>0 0 0</fdir1>
                <slip1>0</slip1>
                <slip2>0</slip2>
              </ode>
              <torsional>
                <ode/>
              </torsional>
            </friction>
            <contact>
              <ode/>
            </contact>
            <bounce/>
          </surface>
          <max_contacts>10</max_contacts>
        </collision>
        <visual name='visual'>
          <geometry>
            <mesh>
              <uri>/home/ubuntu/.ignition/fuel/fuel.ignitionrobotics.org/openrobotics/models/aws_robomaker_warehouse_shelfe_01/2/meshes/aws_robomaker_warehouse_ShelfE_01_visual.DAE</uri>
            </mesh>
          </geometry>
          <meta>
            <layer>1</layer>
          </meta>
        </visual>
        <self_collide>0</self_collide>
        <enable_wind>0</enable_wind>
        <kinematic>0</kinematic>
      </link>
      <static>1</static>
      <pose>1.26304 -3.60919 0 0 -0 0</pose>
    </model>
    <model name='aws_robomaker_warehouse_ClutteringD_01'>
      <link name='link'>
        <collision name='collision'>
          <geometry>
            <mesh>
              <uri>/home/ubuntu/.ignition/fuel/fuel.ignitionrobotics.org/openrobotics/models/aws_robomaker_warehouse_clutteringd_01/2/meshes/aws_robomaker_warehouse_ClutteringD_01_collision.DAE</uri>
              <scale>1 1 1</scale>
            </mesh>
          </geometry>
          <surface>
            <friction>
              <ode>
                <mu>0.6</mu>
                <mu2>0.6</mu2>
                <fdir1>0 0 0</fdir1>
                <slip1>0</slip1>
                <slip2>0</slip2>
              </ode>
              <torsional>
                <coefficient>1</coefficient>
                <patch_radius>0</patch_radius>
                <surface_radius>0</surface_radius>
                <use_patch_radius>1</use_patch_radius>
                <ode>
                  <slip>0</slip>
                </ode>
              </torsional>
            </friction>
            <contact>
              <ode/>
            </contact>
            <bounce/>
          </surface>
          <max_contacts>10</max_contacts>
        </collision>
        <visual name='visual'>
          <geometry>
            <mesh>
              <uri>/home/ubuntu/.ignition/fuel/fuel.ignitionrobotics.org/openrobotics/models/aws_robomaker_warehouse_clutteringd_01/2/meshes/aws_robomaker_warehouse_ClutteringD_01_visual.DAE</uri>
            </mesh>
          </geometry>
          <meta>
            <layer>1</layer>
          </meta>
        </visual>
        <self_collide>0</self_collide>
        <enable_wind>0</enable_wind>
        <kinematic>0</kinematic>
      </link>
      <static>1</static>
      <pose>-2.40738 -0.042258 0 0 -0 0</pose>
    </model>
    <model name='aws_robomaker_warehouse_ClutteringC_01'>
      <link name='link'>
        <collision name='collision'>
          <geometry>
            <mesh>
              <uri>/home/ubuntu/.ignition/fuel/fuel.ignitionrobotics.org/openrobotics/models/aws_robomaker_warehouse_clutteringc_01/2/meshes/aws_robomaker_warehouse_ClutteringC_01_collision.DAE</uri>
            </mesh>
          </geometry>
          <surface>
            <friction>
              <ode>
                <mu>0.6</mu>
                <mu2>0.6</mu2>
                <fdir1>0 0 0</fdir1>
                <slip1>0</slip1>
                <slip2>0</slip2>
              </ode>
              <torsional>
                <coefficient>1</coefficient>
                <patch_radius>0</patch_radius>
                <surface_radius>0</surface_radius>
                <use_patch_radius>1</use_patch_radius>
                <ode>
                  <slip>0</slip>
                </ode>
              </torsional>
            </friction>
            <contact>
              <ode/>
            </contact>
            <bounce/>
          </surface>
          <max_contacts>10</max_contacts>
        </collision>
        <visual name='visual'>
          <geometry>
            <mesh>
              <uri>/home/ubuntu/.ignition/fuel/fuel.ignitionrobotics.org/openrobotics/models/aws_robomaker_warehouse_clutteringc_01/2/meshes/aws_robomaker_warehouse_ClutteringC_01_visual.DAE</uri>
            </mesh>
          </geometry>
          <meta>
            <layer>1</layer>
          </meta>
        </visual>
        <self_collide>0</self_collide>
        <enable_wind>0</enable_wind>
        <kinematic>0</kinematic>
      </link>
      <static>1</static>
      <pose>-1.0155 -1.85973 0 0 -0 0</pose>
    </model>
    <model name='aws_robomaker_warehouse_ClutteringA_01'>
      <link name='link'>
        <collision name='collision'>
          <geometry>
            <mesh>
              <uri>/home/ubuntu/.ignition/fuel/fuel.ignitionrobotics.org/openrobotics/models/aws_robomaker_warehouse_clutteringa_01/2/meshes/aws_robomaker_warehouse_ClutteringA_01_collision.DAE</uri>
            </mesh>
          </geometry>
          <surface>
            <friction>
              <ode>
                <mu>0.6</mu>
                <mu2>0.6</mu2>
                <fdir1>0 0 0</fdir1>
                <slip1>0</slip1>
                <slip2>0</slip2>
              </ode>
              <torsional>
                <coefficient>1</coefficient>
                <patch_radius>0</patch_radius>
                <surface_radius>0</surface_radius>
                <use_patch_radius>1</use_patch_radius>
                <ode>
                  <slip>0</slip>
                </ode>
              </torsional>
            </friction>
            <contact>
              <ode/>
            </contact>
            <bounce/>
          </surface>
          <max_contacts>10</max_contacts>
        </collision>
        <visual name='visual'>
          <geometry>
            <mesh>
              <uri>/home/ubuntu/.ignition/fuel/fuel.ignitionrobotics.org/openrobotics/models/aws_robomaker_warehouse_clutteringa_01/2/meshes/aws_robomaker_warehouse_ClutteringA_01_visual.DAE</uri>
            </mesh>
          </geometry>
          <meta>
            <layer>1</layer>
          </meta>
        </visual>
        <self_collide>0</self_collide>
        <enable_wind>0</enable_wind>
        <kinematic>0</kinematic>
      </link>
      <static>1</static>
      <pose>-3.58585 -2.27117 0 0 -0 0</pose>
    </model>
    <model name='aws_robomaker_warehouse_ShelfD_01'>
      <link name='link'>
        <collision name='collision'>
          <geometry>
            <mesh>
              <uri>/home/ubuntu/.ignition/fuel/fuel.ignitionrobotics.org/openrobotics/models/aws_robomaker_warehouse_shelfd_01/2/meshes/aws_robomaker_warehouse_ShelfD_01_collision.DAE</uri>
              <scale>1 1 1</scale>
            </mesh>
          </geometry>
          <surface>
            <friction>
              <ode>
                <mu>0.2</mu>
                <mu2>0.2</mu2>
                <fdir1>0 0 0</fdir1>
                <slip1>0</slip1>
                <slip2>0</slip2>
              </ode>
              <torsional>
                <ode/>
              </torsional>
            </friction>
            <contact>
              <ode/>
            </contact>
            <bounce/>
          </surface>
          <max_contacts>10</max_contacts>
        </collision>
        <visual name='visual'>
          <geometry>
            <mesh>
              <uri>/home/ubuntu/.ignition/fuel/fuel.ignitionrobotics.org/openrobotics/models/aws_robomaker_warehouse_shelfd_01/2/meshes/aws_robomaker_warehouse_ShelfD_01_visual.DAE</uri>
            </mesh>
          </geometry>
          <meta>
            <layer>1</layer>
          </meta>
        </visual>
        <self_collide>0</self_collide>
        <enable_wind>0</enable_wind>
        <kinematic>0</kinematic>
      </link>
      <static>1</static>
      <pose>1.05881 -5.81791 0 0 -0 0</pose>
    </model>
    <model name='aws_robomaker_warehouse_ShelfF_01'>
      <link name='link'>
        <collision name='collision'>
          <geometry>
            <mesh>
              <uri>/home/ubuntu/.ignition/fuel/fuel.ignitionrobotics.org/openrobotics/models/aws_robomaker_warehouse_shelff_01/2/meshes/aws_robomaker_warehouse_ShelfF_01_collision.DAE</uri>
            </mesh>
          </geometry>
          <surface>
            <friction>
              <ode>
                <mu>0.2</mu>
                <mu2>0.2</mu2>
                <fdir1>0 0 0</fdir1>
                <slip1>0</slip1>
                <slip2>0</slip2>
              </ode>
              <torsional>
                <ode/>
              </torsional>
            </friction>
            <contact>
              <ode/>
            </contact>
            <bounce/>
          </surface>
          <max_contacts>10</max_contacts>
        </collision>
        <visual name='visual'>
          <geometry>
            <mesh>
              <uri>/home/ubuntu/.ignition/fuel/fuel.ignitionrobotics.org/openrobotics/models/aws_robomaker_warehouse_shelff_01/2/meshes/aws_robomaker_warehouse_ShelfF_01_visual.DAE</uri>
            </mesh>
          </geometry>
          <meta>
            <layer>1</layer>
          </meta>
        </visual>
        <self_collide>0</self_collide>
        <enable_wind>0</enable_wind>
        <kinematic>0</kinematic>
      </link>
      <static>1</static>
      <pose>5.97892 -1.97441 0 0 -0 0</pose>
    </model>
    <model name='MetalCabinetYellow'>
      <static>1</static>
      <link name='body'>
        <pose>0 0 0 0 -0 0</pose>
        <visual name='visual'>
          <geometry>
            <mesh>
              <uri>https://fuel.ignitionrobotics.org/1.0/openrobotics/models/metalcabinetyellow/2/files/meshes/MetalCabinetYellow.obj</uri>
            </mesh>
          </geometry>
        </visual>
        <collision name='collision'>
          <geometry>
            <mesh>
              <uri>https://fuel.ignitionrobotics.org/1.0/openrobotics/models/metalcabinetyellow/2/files/meshes/MetalCabinetYellow.obj</uri>
            </mesh>
          </geometry>
          <max_contacts>10</max_contacts>
          <surface>
            <contact>
              <ode/>
            </contact>
            <bounce/>
            <friction>
              <torsional>
                <ode/>
              </torsional>
              <ode/>
            </friction>
          </surface>
        </collision>
        <self_collide>0</self_collide>
        <enable_wind>0</enable_wind>
        <kinematic>0</kinematic>
      </link>
      <pose>-5.35397 -1.15245 0 0 -0 0</pose>
    </model>
    <gui fullscreen='0'>
      <camera name='user_camera'>
        <pose>-9.54938 0.754729 13.1337 0 0.907643 0.052196</pose>
        <view_controller>orbit</view_controller>
        <projection_type>perspective</projection_type>
      </camera>
    </gui>
  </world>
</sdf>
